Workbook

Sheet Summary
A1: DriveDeal monthly operating cost - 10,000 users - OpenAI API (GPT-6 Luna)
A2: USD - AWS us-east-1 hosting + OpenAI API pay-as-you-go for the Sera AI advisor - all figures link to the detail sheets
A4: Usage
A5: Metric | B5: Monthly | C5: Source
A6: Monthly active users | B6: ='AI Cost'!B6 | C6: AI Cost / Infra Cost input
A7: AI chat messages | B7: ='AI Cost'!B58 | C7: AI Cost
A8: OpenAI model calls | B8: ='AI Cost'!B59 | C8: AI Cost
A9: Input tokens | B9: ='AI Cost'!B60 | C9: AI Cost
A10: Output tokens | B10: ='AI Cost'!B63 | C10: AI Cost
A11: Hosted web search calls | B11: ='AI Cost'!B64 | C11: AI Cost
A13: Monthly operating cost
A14: Cost line | B14: Monthly (USD) | C14: Annual (USD) | D14: Per user / month (USD) | E14: Share of total
A15: AWS infrastructure | B15: ='Infra Cost'!H49 | C15: =B15*12 | D15: =IF($B$6>0,B15/$B$6,0) | E15: =IF($B$17>0,B15/$B$17,0)
A16: OpenAI API (Sera AI) | B16: ='AI Cost'!B69 | C16: =B16*12 | D16: =IF($B$6>0,B16/$B$6,0) | E16: =IF($B$17>0,B16/$B$17,0)
A17: Total operating cost | B17: =SUM(B15:B16) | C17: =B17*12 | D17: =IF($B$6>0,B17/$B$6,0) | E17: =SUM(E15:E16)
A19: AWS cost by category
A20: Category | B20: Monthly (USD) | C20: Share of AWS
A21: Compute | B21: =SUMIF('Infra Cost'!$A$13:$A$48,A21,'Infra Cost'!$H$13:$H$48) | C21: =IF($B$15>0,B21/$B$15,0)
A22: Database | B22: =SUMIF('Infra Cost'!$A$13:$A$48,A22,'Infra Cost'!$H$13:$H$48) | C22: =IF($B$15>0,B22/$B$15,0)
A23: Load balancer | B23: =SUMIF('Infra Cost'!$A$13:$A$48,A23,'Infra Cost'!$H$13:$H$48) | C23: =IF($B$15>0,B23/$B$15,0)
A24: Network | B24: =SUMIF('Infra Cost'!$A$13:$A$48,A24,'Infra Cost'!$H$13:$H$48) | C24: =IF($B$15>0,B24/$B$15,0)
A25: CDN | B25: =SUMIF('Infra Cost'!$A$13:$A$48,A25,'Infra Cost'!$H$13:$H$48) | C25: =IF($B$15>0,B25/$B$15,0)
A26: Storage | B26: =SUMIF('Infra Cost'!$A$13:$A$48,A26,'Infra Cost'!$H$13:$H$48) | C26: =IF($B$15>0,B26/$B$15,0)
A27: Monitoring | B27: =SUMIF('Infra Cost'!$A$13:$A$48,A27,'Infra Cost'!$H$13:$H$48) | C27: =IF($B$15>0,B27/$B$15,0)
A28: Security | B28: =SUMIF('Infra Cost'!$A$13:$A$48,A28,'Infra Cost'!$H$13:$H$48) | C28: =IF($B$15>0,B28/$B$15,0)
A29: DNS | B29: =SUMIF('Infra Cost'!$A$13:$A$48,A29,'Infra Cost'!$H$13:$H$48) | C29: =IF($B$15>0,B29/$B$15,0)
A30: Registry | B30: =SUMIF('Infra Cost'!$A$13:$A$48,A30,'Infra Cost'!$H$13:$H$48) | C30: =IF($B$15>0,B30/$B$15,0)
A31: Total (check = AWS infrastructure) | B31: =SUM(B21:B30) | C31: =IF(ABS(B31-B15)<0.005,"OK","Check categories")
A33: Key points
A34: - The share column shows how the cost splits between AWS hosting and the usage-based OpenAI API at this user count.
A35: - Architecture: CloudFront + WAF in front, React app on S3, FastAPI on ECS Fargate behind an ALB, RDS PostgreSQL in private subnets, one NAT Gateway (with Elastic IP) for Sera's internet access. No EC2, ElastiCache or LangSmith.
A36: - The NAT Gateway is the largest fixed network line. Running tasks in public subnets with a public IP instead removes it, at about $3.65 per task per month.
A37: - 4 Fargate tasks need live chat/quote events delivered across tasks: add Postgres LISTEN/NOTIFY fan-out in websocket_manager.py before launch (no ElastiCache needed). Single-AZ RDS has no failover; Multi-AZ roughly doubles the database line.
A38: - OpenAI API is pay-as-you-go (prepaid credits): no subscription fee. Set a project budget alert at the 'Suggested budget' on the AI Cost sheet.
A39: - Token and traffic figures are planning estimates; replace them with OpenAI usage and AWS billing data after the first month.
A40: - Excluded: domain registration, AWS Support plan, taxes, staging environments, engineering time, the Codex subscription, GitHub Actions minutes.
A41: - How to create each AWS service and the OpenAI API key is on the Setup Guide sheet.
A43: Legend
A44: Blue text, yellow fill | B44: Editable input / assumption - change these
A45: Black text | B45: Formula - do not overwrite
...

Sheet Infra Cost
A1: AWS infrastructure cost - 10,000 monthly users
A2: USD per month - us-east-1 - CloudFront + WAF, ECS Fargate (4 tasks), Single-AZ PostgreSQL, 1 NAT Gateway - unit prices: team TCO model (reviewed 12-Oct-2026) plus AWS list prices for Fargate, CloudFront, WAF and NAT
A4: Infrastructure inputs
A5: Input | B5: Value | C5: Unit | D5: Basis
A6: Monthly active users | B6: 10000 | C6: users | D6: Sizing target for this workbook (user request).
A7: Billable hours per month | B7: 730 | C7: hours | D7: AWS monthly planning convention (24 x 365 / 12).
A8: ECS Fargate API tasks | B8: 4 | C8: tasks | D8: 1 vCPU / 2 GB each. Run 1 task until Postgres LISTEN/NOTIFY WebSocket fan-out is added; not load-tested.
A9: CloudFront free data transfer out | B9: 1024 | C9: GB/month | D9: CloudFront always-free tier: 1 TB out and 10 million requests per month.
A11: AWS services needed and monthly cost
A12: Category | B12: AWS service | C12: What it does for DriveDeal | D12: Configuration | E12: Billing unit | F12: Unit price (USD) | G12: Quantity / month | H12: Monthly cost (USD) | I12: Needed? | J12: Notes / source
A13: Compute | B13: AWS Fargate - vCPU | C13: Runs the FastAPI API container. The React app is served from S3 through CloudFront. | D13: Linux/x86, 1 vCPU per task, private subnets, no public IP | E13: vCPU-hour | F13: 0.04048 | G13: =$B$8*$B$7*1 | H13: =F13*G13 | I13: Required | J13: Fargate pricing (aws.amazon.com/fargate/pricing). ARM64 (Graviton) is about 20% cheaper if the image is built for arm64.
A14: Compute | B14: AWS Fargate - memory | C14: Memory for the API tasks. | D14: 2 GB per task | E14: GB-hour | F14: 0.004445 | G14: =$B$8*$B$7*2 | H14: =F14*G14 | I14: Required | J14: Fargate pricing. 20 GB ephemeral storage per task is included.
A15: Load balancer | B15: Application Load Balancer - hourly | C15: Routes /api/* traffic from CloudFront to healthy API tasks. | D15: Internet-facing, 2 AZs, accepts CloudFront traffic only, idle timeout 120 s | E15: ALB-hour | F15: 0.0225 | G15: =$B$7 | H15: =F15*G15 | I15: Required | J15: ELB pricing (aws.amazon.com/elasticloadbalancing/pricing).
A16: Load balancer | B16: Application Load Balancer - LCU | C16: Traffic capacity units used by requests, SSE and WebSockets. | D16: Estimated 1,500 LCU-hours / month | E16: LCU-hour | F16: 0.008 | G16: 1500 | H16: =F16*G16 | I16: Required | J16: ELB pricing. Replace the quantity with CloudWatch ConsumedLCUs after launch.
A17: Network | B17: Public IPv4 addresses (ALB) | C17: Public addresses the ALB needs in its two Availability Zones. | D17: 2 addresses (one per AZ) | E17: IP-hour | F17: 0.005 | G17: =2*$B$7 | H17: =F17*G17 | I17: Required | J17: VPC pricing. AWS bills every public IPv4 hourly.
A18: Network | B18: NAT Gateway - hourly | C18: Outbound internet for Sera from the private subnets (OpenAI API, car-site crawling). | D18: 1 NAT Gateway shared by both AZs | E18: gateway-hour | F18: 0.045 | G18: =$B$7 | H18: =F18*G18 | I18: Required | J18: VPC pricing (aws.amazon.com/vpc/pricing). One NAT per AZ doubles this line for higher availability.
A19: Network | B19: NAT Gateway - data processed | C19: Traffic through the NAT: OpenAI requests/responses and web crawling. | D19: Estimated 200 GB/month | E19: GB | F19: 0.045 | G19: 200 | H19: =F19*G19 | I19: Required | J19: VPC pricing. S3 traffic uses the gateway endpoint and is not billed here.
A20: Network | B20: Elastic IP (NAT Gateway) | C20: Fixed outbound IP for the NAT; partners can allowlist it. | D20: 1 address | E20: IP-hour | F20: 0.005 | G20: =$B$7 | H20: =F20*G20 | I20: Required | J20: VPC pricing. Elastic IPs are billed like any public IPv4.
A21: Network | B21: S3 gateway VPC endpoint | C21: Private path from the API tasks to the uploads bucket; keeps S3 traffic off the NAT. | D21: 1 gateway endpoint on the private route tables | E21: - | F21: 0 | G21: 1 | H21: =F21*G21 | I21: Required | J21: No charge for S3 gateway endpoints.
A22: Network | B22: Cross-AZ data transfer | C22: Traffic between Availability Zones (ALB to tasks, tasks to RDS). | D22: About 50 billable GB/month | E22: GB | F22: 0.01 | G22: 50 | H22: =F22*G22 | I22: Required | J22: EC2 data-transfer pricing.
A23: Network | B23: Amazon VPC (subnets, route tables, security groups) | C23: Private network for the ALB, NAT, ECS tasks and RDS. | D23: 2 public subnets (ALB, NAT) + 2 private subnets (ECS tasks, RDS) in 2 AZs | E23: - | F23: 0 | G23: 1 | H23: =F23*G23 | I23: Required | J23: No charge for the VPC itself.
A24: CDN | B24: Amazon CloudFront - data transfer out | C24: Single entry point for the React app, the API and WebSocket (one domain, HTTPS + wss). | D24: Estimated 500 GB/month; first 1,024 GB free | E24: GB | F24: 0.085 | G24: =MAX(0,500-$B$9) | H24: =F24*G24 | I24: Required | J24: CloudFront pricing (aws.amazon.com/cloudfront/pricing), North America. Origin fetches from the ALB and S3 are free.
A25: CDN | B25: Amazon CloudFront - HTTPS requests | C25: Page, asset and API requests from browsers. | D25: Estimated 50 million requests/month; first 10 million free | E25: 10,000 requests | F25: 0.01 | G25: =MAX(0,50-10)*100 | H25: =F25*G25 | I25: Required | J25: CloudFront pricing. Quantity is in 10,000s after the free tier.
A26: Database | B26: Amazon RDS for PostgreSQL (db.t4g.small) | C26: Marketplace database: users, requests, quotes, chats, Sera memory and traces. | D26: Single-AZ, private subnets, not publicly accessible | E26: instance-hour | F26: 0.032 | G26: =$B$7 | H26: =F26*G26 | I26: Required | J26: RDS pricing (aws.amazon.com/rds/postgresql/pricing). No standby failover; Multi-AZ roughly doubles this line.
A27: Database | B27: RDS gp3 storage | C27: Disk for the PostgreSQL database. | D27: 200 GB gp3 | E27: GB-month | F27: 0.115 | G27: 200 | H27: =F27*G27 | I27: Required | J27: RDS pricing. Monitor growth and free-storage alarms.
A28: Database | B28: RDS backup storage beyond free allowance | C28: Automated backups and snapshots above the free allowance. | D28: 7-day automated backups (fit in the free allowance) | E28: GB-month | F28: 0.095 | G28: 0 | H28: =F28*G28 | I28: Required | J28: RDS pricing. Free backup storage equals provisioned storage; only excess is billed.
A29: Storage | B29: Amazon S3 Standard - uploads storage | C29: Quote photos, dealer documents, buyer driving licences, support attachments, Codex OAuth state. | D29: Private bucket, Block Public Access on, SSE-S3; about 2,000 GB stored | E29: GB-month | F29: 0.023 | G29: 2000 | H29: =F29*G29 | I29: Required | J29: S3 pricing (aws.amazon.com/s3/pricing). Includes versioned objects.
A30: Storage | B30: Amazon S3 - PUT requests | C30: Uploads of photos and documents. | D30: Estimated 200,000 uploads/month | E30: 1,000 requests | F30: 0.005 | G30: 200 | H30: =F30*G30 | I30: Required | J30: S3 pricing. Quantity is in thousands of requests.
A31: Storage | B31: Amazon S3 - GET requests | C31: Downloads through short-lived pre-signed URLs. | D31: Estimated 10,000,000 downloads/month | E31: 1,000 requests | F31: 0.0004 | G31: 10000 | H31: =F31*G31 | I31: Required | J31: S3 pricing. Quantity is in thousands of requests.
A32: Storage | B32: Amazon S3 - frontend bucket | C32: React build files; private, readable only by CloudFront (Origin Access Control). | D32: About 1 GB including recent builds | E32: GB-month | F32: 0.023 | G32: 1 | H32: =F32*G32 | I32: Required | J32: S3 pricing. Requests come from CloudFront and are mostly cached.
A33: Monitoring | B33: CloudWatch Logs - Infrequent Access | C33: Collects the API container's JSON logs from ECS. | D33: Planning estimate: 10 MB per monthly active user | E33: GB | F33: 0.25 | G33: =$B$6*0.01 | H33: =F33*G33 | I33: Required | J33: AWS Pricing Calculator, US East (N. Virginia): Infrequent Access ingestion $0.25/GB. 10 MB per user is a planning assumption.
A34: Monitoring | B34: Amazon CloudWatch Logs - retention | C34: Stores compressed logs for troubleshooting. | D34: 30-day retention; 15% of ingested volume stored (calculator estimate) | E34: GB-month | F34: 0.03 | G34: =G33*0.15 | H34: =F34*G34 | I34: Required | J34: AWS Pricing Calculator estimates stored volume at 15% of ingested volume; $0.03/GB-month.
A35: Monitoring | B35: Amazon CloudWatch custom metrics | C35: App metrics (latency, Sera calls, errors). | D35: 40 custom metrics | E35: metric-month | F35: 0.3 | G35: 40 | H35: =F35*G35 | I35: Required | J35: CloudWatch pricing.
A36: Monitoring | B36: CloudWatch Container Insights (ECS) | C36: CPU, memory and task metrics for the ECS cluster and service. | D36: Budget estimate | E36: USD budget | F36: 1 | G36: 12 | H36: =F36*G36 | I36: Recommended | J36: Budget estimate, not measured usage. Replace with billing data after the first month.
A37: Monitoring | B37: Amazon CloudWatch alarms | C37: Alerts: ALB 5xx, ECS running tasks, ECS CPU, RDS CPU / free storage. | D37: 20 standard alarms | E37: alarm-month | F37: 0.1 | G37: 20 | H37: =F37*G37 | I37: Required | J37: CloudWatch pricing.
A38: Security | B38: AWS WAF - web ACL | C38: Filters bad traffic in front of CloudFront. | D38: 1 web ACL (CloudFront scope, us-east-1) | E38: web ACL-month | F38: 5 | G38: 1 | H38: =F38*G38 | I38: Required | J38: WAF pricing (aws.amazon.com/waf/pricing).
A39: Security | B39: AWS WAF - rules | C39: AWS managed rule groups plus a rate limit. | D39: 4 rules (3 managed rule groups + 1 rate rule) | E39: rule-month | F39: 1 | G39: 4 | H39: =F39*G39 | I39: Required | J39: WAF pricing.
A40: Security | B40: AWS WAF - requests | C40: Every request CloudFront receives is inspected. | D40: Estimated 50 million requests/month | E40: million requests | F40: 0.6 | G40: 50 | H40: =F40*G40 | I40: Required | J40: WAF pricing.
A41: Security | B41: AWS Secrets Manager - secrets | C41: JWT_SECRET_KEY, OPENAI_API_KEY (or Codex OAuth), RDS master password, CloudFront origin header. | D41: 4 secrets (RDS manages its own password secret) | E41: secret-month | F41: 0.4 | G41: 4 | H41: =F41*G41 | I41: Required | J41: Secrets Manager pricing (aws.amazon.com/secrets-manager/pricing).
A42: Security | B42: AWS Secrets Manager - API calls | C42: Read when ECS tasks start. | D42: About 5,000 calls/month | E42: 10,000 calls | F42: 0.05 | G42: 0.5 | H42: =F42*G42 | I42: Required | J42: Secrets Manager pricing. Quantity is in 10,000s.
...

Sheet AI Cost
A1: OpenAI API cost - Sera AI advisor - 10,000 monthly users - GPT-6 Luna
A2: USD per month - OpenAI API pay-as-you-go - workload and token assumptions from DriveDeal-TCO (1).xlsx (team TCO model, rates reviewed 12-Oct-2026)
A4: Workload inputs
A5: Input | B5: Value | C5: Unit | D5: Basis
A6: Monthly active users | B6: ='Infra Cost'!B6 | C6: users | D6: Linked from Infra Cost so both sheets size the same user count.
A7: Car requests per user / month | B7: 4 | C7: requests | D7: Team planning target: four published requests per user.
A8: AI messages per car request | B8: 2 | C8: messages | D8: Team planning assumption.
A9: Additional AI messages per user / month | B9: 0 | C9: messages | D9: Advice or research not tied to a posted request.
A10: Guided / no-model share | B10: 0.2 | C10: % of messages | D10: Guided cards and publish confirmations make no model call.
A11: Small-talk share | B11: 0.1 | C11: % of messages | D11: Greetings and off-topic replies: one model call.
A12: Catalog advice share of remaining | B12: 0.5 | C12: % | D12: Remaining messages split 50 / 25 / 25.
A13: Direct web research share of remaining | B13: 0.25 | C13: % | D13: Explicit research skips classifier and orchestrator.
A14: Per-car research share of remaining | B14: 0.25 | C14: % | D14: Catalog shortlist followed by research per vehicle.
A15: Request-extraction probability | B15: 0.3 | C15: probability | D15: Extra call when required request fields are missing.
A16: Catalog planning probability | B16: 0.3 | C16: probability | D16: Named models skip the planning call.
A17: Vehicles per per-car research message | B17: 3 | C17: vehicles | D17: Average; code caps the shortlist at six.
A18: Pages extracted per researched vehicle | B18: 1 | C18: pages | D18: First usable page.
... A23: Cached input share | B23: 0 | C23: % | D23: No caching savings assumed until observed.
A25: OpenAI API prices
A26: Price | B26: Value | C26: Unit | D26: Basis
A27: Model input (GPT-6 Luna) | B27: 0.1 | C27: USD / 1M tokens | D27: OpenAI API pricing, reviewed 12-Oct-2026 (developers.openai.com/api/docs/pricing). Set OPENAI_MODEL to the GPT-6 Luna model ID.
A28: Model output incl. reasoning (GPT-6 Luna) | B28: 0.5 | C28: USD / 1M tokens | D28: OpenAI API pricing, reviewed 12-Oct-2026.
A29: Cached input (GPT-6 Luna) | B29: 0.01 | C29: USD / 1M tokens | D29: OpenAI API pricing, reviewed 12-Oct-2026.
A30: Hosted web search tool call | B30: 0.01 | C30: USD / call | D30: OpenAI API pricing ($10 per 1,000 calls). Search content also bills as input tokens.
A31: Budget cap multiplier | B31: 2 | C31: x estimate | D31: Headroom for the OpenAI project budget alert/limit (team choice).
A33: Per-call token estimates
A34: Model call | B34: Input tokens | C34: Output tokens | D34: Measured input (ref.) | E34: Measured output (ref.) | F34: Basis
A35: Classifier | B35: 450 | C35: 60 | D35: 258 | E35: 10 | F35: Team planning estimate (used in the cost).
A36: Orchestrator | B36: 1400 | C36: 300 | D36: 1527 | E36: 63 | F36: Team planning estimate (used in the cost).
A37: Catalog tool plan | B37: 1600 | C37: 500 | D37: 2015 | E37: 46 | F37: Team planning estimate (used in the cost).
A38: Page / spec extraction | B38: 11250 | C38: 1200 | D38: 7067 | E38: 439 | F38: Team planning estimate (used in the cost).
A39: Request extraction | B39: 810 | C39: 400 | D39: n/a | E39: n/a | F39: Team planning estimate (used in the cost).
A40: Answer composition | B40: 3200 | C40: 2000 | D40: 2615 | E40: 201 | F40: Team planning estimate (used in the cost).
A41: Hosted web search call (excl. search content) | B41: 600 | C41: 1500 | D41: n/a | E41: 604 | F41: Team estimate; measured total input incl. search content was about 11,300 tokens (see note).
A42: Small talk | B42: 500 | C42: 200 | D42: 580 | E42: 34 | F42: Team planning estimate (used in the cost).
A43: Measured columns = averages from Sera production traces (ai_trace_spans, 14 days to 13-Oct-2026), for reference only. Measured output is lower than planned on most calls; measured hosted-search input (~11,300 incl. content) is higher than planned (600 + 4,000).
A45: Calls and tokens per AI message, by route
A46: Message route | B46: Share | C46: Model calls | D46: Input tokens | E46: Output tokens | F46: Search calls | G46: Page extractions
A47: Guided / no model | B47: =$B$10 | C47: =0 | D47: =0 | E47: =0 | F47: =0 | G47: =0
A48: Small talk | B48: =$B$11 | C48: =1 | D48: =$B$42 | E48: =$C$42 | F48: =0 | G48: =0
...

Sheet Setup Guide
A1: Setup guide - AWS services and OpenAI API key (10,000 users)
A2: Step-by-step for the 10,000-user deployment on CloudFront + ECS Fargate. Create the resources with Terraform (infra/terraform) where possible; the steps below describe what gets created. Console menu names can change.
A4: Section | B4: Step | C4: What to do | D4: Where (console / file) | E4: Notes
A5: 1. AWS account | B5: 1 | C5: Create the AWS account with a company email, then turn on MFA for the root user and stop using root for daily work. | D5: aws.amazon.com > Create account; IAM > Security credentials | E5: Keep root credentials in the company password manager.
A6: 1. AWS account | B6: 2 | C6: Create admin access for the team (IAM Identity Center users, or IAM users with MFA) and give each person their own login. | D6: IAM Identity Center (or IAM > Users) | E6: Never share one login between people.
A7: 1. AWS account | B7: 3 | C7: Choose one region (this estimate uses us-east-1) and create every resource there. CloudFront certificates and the WAF web ACL always live in us-east-1. | D7: Region selector, top right of the console | E7: Prices in this workbook are us-east-1.
A8: 1. AWS account | B8: 4 | C8: Create a monthly cost budget at the Summary total plus about 20%, with email alerts at 80% and 100%. | D8: Billing and Cost Management > Budgets | E8: Catches runaway usage early.
A9: 2. Infrastructure as code | B9: 1 | C9: Create a private S3 bucket for Terraform state and a GitHub Actions OIDC identity provider (infra/terraform/bootstrap). State locking uses use_lockfile = true. | D9: infra/terraform/bootstrap | E9: No DynamoDB lock table is needed with Terraform 1.10+.
A10: 2. Infrastructure as code | B10: 2 | C10: Apply the environment: terraform init, plan, apply. It creates every resource in the sections below. | D10: infra/terraform/envs/<env> | E10: Pin Terraform ~> 1.17 and the AWS provider ~> 6.70 (avoid 6.57.0, it was withdrawn).
A11: 3. Network (VPC) | B11: 1 | C11: Create a VPC with 2 public subnets (ALB, NAT) and 2 private subnets (ECS tasks, RDS) across 2 Availability Zones, plus an internet gateway. | D11: VPC > Create VPC > 'VPC and more' | E11: Set NAT gateways to 'In 1 AZ'.
A12: 3. Network (VPC) | B12: 2 | C12: Create 1 NAT Gateway in a public subnet (AWS allocates its Elastic IP) and route 0.0.0.0/0 from both private route tables to it. | D12: VPC > NAT gateways; Route tables | E12: Sera needs this to reach OpenAI and car websites.
A13: 3. Network (VPC) | B13: 3 | C13: Add an S3 gateway endpoint and attach it to the private route tables. | D13: VPC > Endpoints > Create endpoint > S3 (Gateway) | E13: Free; keeps S3 upload traffic off the NAT.
A14: 3. Network (VPC) | B14: 4 | C14: Create security groups: ALB allows 443 only from the CloudFront managed prefix list (com.amazonaws.global.cloudfront.origin-facing); ECS allows 8000 only from the ALB group; RDS allows 5432 only from the ECS group. | D14: VPC > Security groups | E14: Never open 5432 or 8000 to the internet.
A15: 4. RDS PostgreSQL | B15: 1 | C15: Create a PostgreSQL database: db.t4g.small, Single-AZ, 200 GB gp3, in the private subnets, Public access = No, RDS security group. | D15: RDS > Create database > Standard create > PostgreSQL | E15: Matches the Infra Cost lines.
A16: 4. RDS PostgreSQL | B16: 2 | C16: Let RDS manage the master password in Secrets Manager, set automated backups to 7 days and turn on deletion protection. | D16: RDS > Create database > Credentials / Backup | E16: The password never appears in code or Terraform state.
... A25: 8. IAM roles | B25: 3 | C25: GitHub Actions deploy role, trusted through OIDC for this repository: push to ECR, run the migration task, update the ECS service, sync the frontend bucket, invalidate CloudFront. | D25: IAM > Identity providers (token.actions.githubusercontent.com); IAM > Roles | E25: No AWS access keys in GitHub secrets.
A26: 9. ECS Fargate | B26: 1 | C26: Create an ECS cluster with Container Insights turned on. | D26: ECS > Clusters > Create cluster (Fargate)
A27: 9. ECS Fargate | B27: 2 | C27: Create the task definition: 1 vCPU / 2 GB, container port 8000, awslogs to /ecs/drivedeal-prod-api (30-day retention), secrets injected from Secrets Manager. | D27: ECS > Task definitions > Create | E27: Health check: /api/v1/health.
A28: 9. ECS Fargate | B28: 3 | C28: Set production env vars: APP_ENV=production, STORAGE_DRIVER=s3, S3_BUCKET, AWS_REGION, CORS_ORIGINS=["https://www.dealndrive.ai","https://dealndrive.ai"], AI_PROVIDER=openai, OPENAI_MODEL, AI_ENABLE_WEB_SEARCH=true, AI_REQUEST_TIMEOUT_SECONDS=45, LANGSMITH_TRACING=false. | D28: deploy/task-definition/backend.yml lists every variable | E28: Production start-up fails unless STORAGE_DRIVER=s3.
A29: 9. ECS Fargate | B29: 4 | C29: Create the service: 4 desired task(s) across both private subnets, no public IP, attached to the ALB target group, deployment circuit breaker with rollback, 60 s health check grace period. | D29: ECS > Clusters > Create service | E29: Infra Cost assumption: 4 tasks.
A30: 9. ECS Fargate | B30: 5 | C30: Code change before launch: make websocket_manager publish chat/quote events with Postgres NOTIFY and have each task LISTEN and deliver to its own connected users. | D30: backend/src/services/websocket_manager.py | E30: Without this, users on another task miss live updates. No ElastiCache needed.
A31: 9. ECS Fargate | B31: 6 | C31: Load-test the full stack (chat streaming, uploads, quotes) at the expected peak before go-live; size RDS up if CPU or connections run high. | D31: Load-testing tool (e.g. k6, Locust) | E31: RDS db.t4g.small is the team estimate, not a measured capacity.
A32: 10. TLS certificates | B32: 1 | C32: Request a public certificate for dealndrive.ai and www.dealndrive.ai in us-east-1 (for CloudFront) and one in the app region (for the ALB). Validate both through DNS. | D32: Certificate Manager > Request certificate | E32: Free.
A33: 11. Load balancer | B33: 1 | C33: Create an internet-facing Application Load Balancer in the 2 public subnets with the ALB security group. | D33: EC2 > Load balancers > Create > Application Load Balancer
A34: 11. Load balancer | B34: 2 | C34: Create a target group of type IP, port 8000, health check path /api/v1/health, deregistration delay 30 s. | D34: EC2 > Target groups | E34: ECS registers the task IPs automatically.
A35: 11. Load balancer | B35: 3 | C35: HTTPS 443 listener with the regional certificate: forward only when the X-Origin-Verify header matches the secret; default action returns 403. | D35: Load balancer > Listeners > Rules | E35: Blocks anyone bypassing CloudFront.
A36: 11. Load balancer | B36: 4 | C36: Raise the ALB idle timeout to 120 seconds so Sera's streaming (SSE) replies and WebSocket chat are not cut off. | D36: Load balancer > Attributes > Idle timeout | E36: The default 60 seconds can cut long research answers.
A37: 12. CloudFront + WAF | B37: 1 | C37: Create the distribution. Default behaviour (/*): frontend S3 bucket with OAC, cached. Map 403/404 errors to /index.html with status 200 for React routes. | D37: CloudFront > Create distribution
A38: 12. CloudFront + WAF | B38: 2 | C38: Add the /api/* behaviour to the ALB origin: all HTTP methods, cache policy CachingDisabled, origin request policy AllViewerExceptHostHeader, custom header X-Origin-Verify, origin response timeout 60 s. | D38: CloudFront > Distribution > Behaviors / Origins | E38: Forwards the WebSocket ?token= query string and upgrade headers.
A39: 12. CloudFront + WAF | B39: 3 | C39: Create a WAF web ACL (CloudFront scope) with AWS managed Common, Known bad inputs and IP reputation rule groups plus a rate-based rule, and attach it to the distribution. | D39: WAF & Shield > Web ACLs > Create | E39: Matches the 4 WAF rules in Infra Cost.
A40: 12. CloudFront + WAF | B40: 4 | C40: Add www.dealndrive.ai and dealndrive.ai as alternate domain names and select the us-east-1 certificate. Add a CloudFront Function that redirects dealndrive.ai to https://www.dealndrive.ai. | D40: CloudFront > Distribution > Settings; CloudFront > Functions | E40: www.dealndrive.ai is the one canonical address.
A41: 13. DNS (dealndrive.ai) | B41: 1 | C41: The domain stays registered at GoDaddy. Create a Route 53 public hosted zone for dealndrive.ai. | D41: Route 53 > Hosted zones > Create hosted zone | E41: Only the DNS moves; registration and renewal stay at GoDaddy.
A42: 13. DNS (dealndrive.ai) | B42: 2 | C42: Copy every existing Microsoft 365 email record from the GoDaddy zone into Route 53 first: MX (dealndrive-ai.mail.protection.outlook.com), SPF and onmicrosoft TXT, _dmarc TXT, selector1/selector2._domainkey, autodiscover, lyncdiscover, msoid, sip, the two SRV records and the pay CNAME. | D42: GoDaddy > Domain > DNS > Export zone file; Route 53 > Import zone file | E42: Skipping this stops company email when the nameservers change.
A43: 13. DNS (dealndrive.ai) | B43: 3 | C43: Add the ACM validation CNAMEs and A/AAAA alias records for dealndrive.ai and www.dealndrive.ai pointing to the CloudFront distribution. Lower the GoDaddy record TTLs to 300 s a day before the switch. | D43: Route 53 > Hosted zones > dealndrive.ai | E43: Alias queries to CloudFront are free.
A44: 13. DNS (dealndrive.ai) | B44: 4 | C44: Switch nameservers: replace ns23/ns24.domaincontrol.com with the 4 Route 53 nameservers. The current site (A record 216.198.79.1) keeps serving until DNS propagates (up to 48 hours). | D44: GoDaddy > Domain > Nameservers > Change > I'll use my own nameservers | E44: Test email in and out right after the switch.
A45: 14. Monitoring | B45: 1 | C45: Create 20 alarms, starting with: ALB 5xx count, unhealthy targets, ECS running tasks < desired, ECS CPU / memory > 80%, RDS CPU > 80%, RDS free storage < 10 GB. Send them to an SNS email topic. | D45: CloudWatch > Alarms > Create alarm | E45: Matches the 20 alarms in Infra Cost.
A46: 15. Security scanning | B46: 1 | C46: Turn on Amazon Inspector for ECR image scanning (or keep ECR basic scan on push). | D46: Amazon Inspector > Get started | E46: About $3/month at 30 image pushes (estimate).
A47: 16. CI/CD (GitHub Actions) | B47: 1 | C47: Update the pipeline: assume the deploy role through OIDC, build and push the API image to ECR, run the migration task, then update the ECS service and wait until it is stable. | D47: .github/workflows/ci-cd.yml | E47: Replaces the Docker Hub push and EC2 SSH deploy.
A48: 16. CI/CD (GitHub Actions) | B48: 2 | C48: Build the frontend with VITE_API_BASE_URL=https://www.dealndrive.ai/api/v1 and VITE_WS_BASE_URL=wss://www.dealndrive.ai/api/v1/ws, sync it to the frontend bucket and invalidate /index.html. | D48: GitHub > Settings > Variables; frontend/ | E48: Remove DEV_EC2_HOST, DEV_EC2_SSH_KEY and Docker Hub secrets afterwards.
A49: 17. OpenAI account | B49: 1 | C49: Create an OpenAI API platform account with a company email. This is separate from a ChatGPT subscription. | D49: platform.openai.com > Sign up | E49: API usage is billed separately from ChatGPT plans.
...
